<?xml version="1.0" ?>
<sdf version="1.6">
  <model name="livo2_rover">
    <static>false</static>

    <!-- ==================== CHASSIS ==================== -->
    <link name="base_link">
      <inertial>
        <mass>10.0</mass>
        <inertia>
          <ixx>0.5</ixx><ixy>0</ixy><ixz>0</ixz>
          <iyy>1.0</iyy><iyz>0</iyz>
          <izz>0.5</izz>
        </inertia>
      </inertial>
      <collision name="chassis_collision">
        <geometry>
          <box><size>0.6 0.4 0.15</size></box>
        </geometry>
      </collision>
      <visual name="chassis_visual">
        <geometry>
          <box><size>0.6 0.4 0.15</size></box>
        </geometry>
        <material>
          <ambient>0.2 0.2 0.2 1</ambient>
          <diffuse>0.3 0.3 0.3 1</diffuse>
        </material>
      </visual>

      <!-- ==================== IMU SENSOR ==================== -->
      <sensor name="imu_sensor" type="imu">
        <always_on>true</always_on>
        <update_rate>200</update_rate>
        <imu>
          <angular_velocity>
            <x><noise type="gaussian"><mean>0.0</mean><stddev>0.003</stddev></noise></x>
            <y><noise type="gaussian"><mean>0.0</mean><stddev>0.003</stddev></noise></y>
            <z><noise type="gaussian"><mean>0.0</mean><stddev>0.003</stddev></noise></z>
          </angular_velocity>
          <linear_acceleration>
            <x><noise type="gaussian"><mean>0.0</mean><stddev>0.05</stddev></noise></x>
            <y><noise type="gaussian"><mean>0.0</mean><stddev>0.05</stddev></noise></y>
            <z><noise type="gaussian"><mean>0.0</mean><stddev>0.05</stddev></noise></z>
          </linear_acceleration>
        </imu>
        <plugin name="imu_plugin" filename="libgazebo_ros_imu_sensor.so">
          <topicName>/rover/imu</topicName>
          <bodyName>base_link</bodyName>
          <frameName>base_link</frameName>
          <updateRateHZ>200.0</updateRateHZ>
          <gaussianNoise>0.0</gaussianNoise>
          <xyzOffset>0 0 0</xyzOffset>
          <rpyOffset>0 0 0</rpyOffset>
        </plugin>
      </sensor>
    </link>

    <!-- ==================== WHEELS ==================== -->
    <!-- Front left wheel -->
    <link name="front_left_wheel">
      <pose>0.2 0.25 -0.05 -1.5708 0 0</pose>
      <inertial>
        <mass>0.5</mass>
        <inertia>
          <ixx>0.001</ixx><ixy>0</ixy><ixz>0</ixz>
          <iyy>0.001</iyy><iyz>0</iyz><izz>0.001</izz>
        </inertia>
      </inertial>
      <collision name="collision">
        <geometry><cylinder><radius>0.1</radius><length>0.05</length></cylinder></geometry>
        <surface>
          <friction><ode><mu>1.0</mu><mu2>1.0</mu2></ode></friction>
        </surface>
      </collision>
      <visual name="visual">
        <geometry><cylinder><radius>0.1</radius><length>0.05</length></cylinder></geometry>
        <material><ambient>0.1 0.1 0.1 1</ambient></material>
      </visual>
    </link>
    <joint name="front_left_wheel_joint" type="revolute">
      <parent>base_link</parent>
      <child>front_left_wheel</child>
      <axis><xyz>0 0 1</xyz></axis>
    </joint>

    <!-- Front right wheel -->
    <link name="front_right_wheel">
      <pose>0.2 -0.25 -0.05 -1.5708 0 0</pose>
      <inertial>
        <mass>0.5</mass>
        <inertia>
          <ixx>0.001</ixx><ixy>0</ixy><ixz>0</ixz>
          <iyy>0.001</iyy><iyz>0</iyz><izz>0.001</izz>
        </inertia>
      </inertial>
      <collision name="collision">
        <geometry><cylinder><radius>0.1</radius><length>0.05</length></cylinder></geometry>
        <surface>
          <friction><ode><mu>1.0</mu><mu2>1.0</mu2></ode></friction>
        </surface>
      </collision>
      <visual name="visual">
        <geometry><cylinder><radius>0.1</radius><length>0.05</length></cylinder></geometry>
        <material><ambient>0.1 0.1 0.1 1</ambient></material>
      </visual>
    </link>
    <joint name="front_right_wheel_joint" type="revolute">
      <parent>base_link</parent>
      <child>front_right_wheel</child>
      <axis><xyz>0 0 1</xyz></axis>
    </joint>

    <!-- Rear left wheel -->
    <link name="rear_left_wheel">
      <pose>-0.2 0.25 -0.05 -1.5708 0 0</pose>
      <inertial>
        <mass>0.5</mass>
        <inertia>
          <ixx>0.001</ixx><ixy>0</ixy><ixz>0</ixz>
          <iyy>0.001</iyy><iyz>0</iyz><izz>0.001</izz>
        </inertia>
      </inertial>
      <collision name="collision">
        <geometry><cylinder><radius>0.1</radius><length>0.05</length></cylinder></geometry>
        <surface>
          <friction><ode><mu>1.0</mu><mu2>1.0</mu2></ode></friction>
        </surface>
      </collision>
      <visual name="visual">
        <geometry><cylinder><radius>0.1</radius><length>0.05</length></cylinder></geometry>
        <material><ambient>0.1 0.1 0.1 1</ambient></material>
      </visual>
    </link>
    <joint name="rear_left_wheel_joint" type="revolute">
      <parent>base_link</parent>
      <child>rear_left_wheel</child>
      <axis><xyz>0 0 1</xyz></axis>
    </joint>

    <!-- Rear right wheel -->
    <link name="rear_right_wheel">
      <pose>-0.2 -0.25 -0.05 -1.5708 0 0</pose>
      <inertial>
        <mass>0.5</mass>
        <inertia>
          <ixx>0.001</ixx><ixy>0</ixy><ixz>0</ixz>
          <iyy>0.001</iyy><iyz>0</iyz><izz>0.001</izz>
        </inertia>
      </inertial>
      <collision name="collision">
        <geometry><cylinder><radius>0.1</radius><length>0.05</length></cylinder></geometry>
        <surface>
          <friction><ode><mu>1.0</mu><mu2>1.0</mu2></ode></friction>
        </surface>
      </collision>
      <visual name="visual">
        <geometry><cylinder><radius>0.1</radius><length>0.05</length></cylinder></geometry>
        <material><ambient>0.1 0.1 0.1 1</ambient></material>
      </visual>
    </link>
    <joint name="rear_right_wheel_joint" type="revolute">
      <parent>base_link</parent>
      <child>rear_right_wheel</child>
      <axis><xyz>0 0 1</xyz></axis>
    </joint>

    <!-- Differential drive plugin (ROS1 Noetic syntax) -->
    <plugin name="diff_drive" filename="libgazebo_ros_diff_drive.so">
      <updateRate>100</updateRate>
      <leftJoint>front_left_wheel_joint</leftJoint>
      <rightJoint>front_right_wheel_joint</rightJoint>
      <wheelSeparation>0.5</wheelSeparation>
      <wheelDiameter>0.2</wheelDiameter>
      <wheelTorque>20</wheelTorque>
      <wheelAcceleration>1.0</wheelAcceleration>
      <commandTopic>/rover/cmd_vel</commandTopic>
      <odometryTopic>/rover/odom</odometryTopic>
      <odometryFrame>odom</odometryFrame>
      <robotBaseFrame>base_link</robotBaseFrame>
      <publishOdom>true</publishOdom>
      <publishOdomTF>true</publishOdomTF>
      <publishWheelTF>false</publishWheelTF>
      <publishWheelJointState>false</publishWheelJointState>
      <legacyMode>false</legacyMode>
    </plugin>

    <!-- Second diff drive for rear wheels (slaved to front) -->
    <plugin name="rear_diff_drive" filename="libgazebo_ros_diff_drive.so">
      <updateRate>100</updateRate>
      <leftJoint>rear_left_wheel_joint</leftJoint>
      <rightJoint>rear_right_wheel_joint</rightJoint>
      <wheelSeparation>0.5</wheelSeparation>
      <wheelDiameter>0.2</wheelDiameter>
      <wheelTorque>20</wheelTorque>
      <wheelAcceleration>1.0</wheelAcceleration>
      <commandTopic>/rover/cmd_vel</commandTopic>
      <odometryTopic>/rover/rear_odom</odometryTopic>
      <odometryFrame>odom</odometryFrame>
      <robotBaseFrame>base_link</robotBaseFrame>
      <publishOdom>false</publishOdom>
      <publishOdomTF>false</publishOdomTF>
      <publishWheelTF>false</publishWheelTF>
      <legacyMode>false</legacyMode>
    </plugin>

    <!-- ==================== SENSOR MAST ==================== -->
    <link name="sensor_mast">
      <pose>0 0 0.175 0 0 0</pose>
      <inertial>
        <mass>0.3</mass>
        <inertia>
          <ixx>0.001</ixx><ixy>0</ixy><ixz>0</ixz>
          <iyy>0.001</iyy><iyz>0</iyz><izz>0.001</izz>
        </inertia>
      </inertial>
      <collision name="mast_collision">
        <geometry><cylinder><radius>0.03</radius><length>0.2</length></cylinder></geometry>
      </collision>
      <visual name="mast_visual">
        <geometry><cylinder><radius>0.03</radius><length>0.2</length></cylinder></geometry>
        <material><ambient>0.5 0.5 0.5 1</ambient></material>
      </visual>
    </link>
    <joint name="mast_joint" type="fixed">
      <parent>base_link</parent>
      <child>sensor_mast</child>
    </joint>

    <!-- ==================== VLP-16 LIDAR ==================== -->
    <link name="velodyne_link">
      <pose>0 0 0.32 0 0 0</pose>
      <inertial>
        <mass>0.83</mass>
        <inertia>
          <ixx>0.001</ixx><ixy>0</ixy><ixz>0</ixz>
          <iyy>0.001</iyy><iyz>0</iyz><izz>0.001</izz>
        </inertia>
      </inertial>
      <collision name="lidar_collision">
        <geometry><cylinder><radius>0.05</radius><length>0.07</length></cylinder></geometry>
      </collision>
      <visual name="lidar_visual">
        <geometry><cylinder><radius>0.05</radius><length>0.07</length></cylinder></geometry>
        <material>
          <ambient>0.0 0.0 0.8 1</ambient>
          <diffuse>0.0 0.0 0.8 1</diffuse>
        </material>
      </visual>

      <sensor name="velodyne" type="ray">
        <always_on>true</always_on>
        <visualize>false</visualize>
        <update_rate>10</update_rate>
        <ray>
          <scan>
            <horizontal>
              <samples>900</samples>
              <resolution>1</resolution>
              <min_angle>-3.14159</min_angle>
              <max_angle>3.14159</max_angle>
            </horizontal>
            <vertical>
              <samples>16</samples>
              <resolution>1</resolution>
              <min_angle>-0.261799</min_angle>
              <max_angle>0.261799</max_angle>
            </vertical>
          </scan>
          <range>
            <min>0.5</min>
            <max>100.0</max>
            <resolution>0.003</resolution>
          </range>
          <noise>
            <type>gaussian</type>
            <mean>0.0</mean>
            <stddev>0.005</stddev>
          </noise>
        </ray>
        <plugin name="velodyne_plugin" filename="libgazebo_ros_velodyne_laser.so">
          <topicName>/rover/velodyne_points</topicName>
          <frameName>velodyne_link</frameName>
          <min_range>0.5</min_range>
          <max_range>100.0</max_range>
          <gaussianNoise>0.005</gaussianNoise>
          <organize_cloud>false</organize_cloud>
        </plugin>
      </sensor>
    </link>
    <joint name="velodyne_joint" type="fixed">
      <parent>sensor_mast</parent>
      <child>velodyne_link</child>
    </joint>

    <!-- ==================== CAMERA ==================== -->
    <link name="camera_link">
      <pose>0.15 0 0.2 0 0 0</pose>
      <inertial>
        <mass>0.1</mass>
        <inertia>
          <ixx>0.0001</ixx><ixy>0</ixy><ixz>0</ixz>
          <iyy>0.0001</iyy><iyz>0</iyz><izz>0.0001</izz>
        </inertia>
      </inertial>
      <collision name="camera_collision">
        <geometry><box><size>0.04 0.08 0.04</size></box></geometry>
      </collision>
      <visual name="camera_visual">
        <geometry><box><size>0.04 0.08 0.04</size></box></geometry>
        <material>
          <ambient>0.8 0.0 0.0 1</ambient>
          <diffuse>0.8 0.0 0.0 1</diffuse>
        </material>
      </visual>

      <sensor name="camera" type="camera">
        <always_on>true</always_on>
        <visualize>false</visualize>
        <update_rate>20</update_rate>
        <camera>
          <horizontal_fov>1.3962634</horizontal_fov>
          <image>
            <width>640</width>
            <height>480</height>
            <format>R8G8B8</format>
          </image>
          <clip>
            <near>0.02</near>
            <far>300</far>
          </clip>
          <noise>
            <type>gaussian</type>
            <mean>0.0</mean>
            <stddev>0.007</stddev>
          </noise>
        </camera>
        <plugin name="camera_plugin" filename="libgazebo_ros_camera.so">
          <cameraName>rover_camera</cameraName>
          <imageTopicName>/rover/camera/image_raw</imageTopicName>
          <cameraInfoTopicName>/rover/camera/camera_info</cameraInfoTopicName>
          <frameName>camera_link</frameName>
          <alwaysOn>true</alwaysOn>
          <updateRate>20.0</updateRate>
          <hackBaseline>0.0</hackBaseline>
          <distortionK1>0.0</distortionK1>
          <distortionK2>0.0</distortionK2>
          <distortionK3>0.0</distortionK3>
          <distortionT1>0.0</distortionT1>
          <distortionT2>0.0</distortionT2>
        </plugin>
      </sensor>
    </link>
    <joint name="camera_joint" type="fixed">
      <parent>base_link</parent>
      <child>camera_link</child>
    </joint>

  </model>
</sdf>
